{
 "cells": [
  {
   "cell_type": "code",
   "execution_count": 1,
   "id": "07827d16-8a84-4280-ab52-cece5b6dbaf1",
   "metadata": {},
   "outputs": [
    {
     "name": "stdout",
     "output_type": "stream",
     "text": [
      "Processing ./dist/o11y-0.1.0-py3-none-any.whl\n",
      "Collecting python-logging-loki>=0.3.1 (from o11y==0.1.0)\n",
      "  Using cached python_logging_loki-0.3.1-py3-none-any.whl.metadata (3.4 kB)\n",
      "Collecting requests>=2.31.0 (from o11y==0.1.0)\n",
      "  Using cached requests-2.31.0-py3-none-any.whl.metadata (4.6 kB)\n",
      "Collecting rfc3339>=6.1 (from python-logging-loki>=0.3.1->o11y==0.1.0)\n",
      "  Using cached rfc3339-6.2-py3-none-any.whl.metadata (816 bytes)\n",
      "Collecting charset-normalizer<4,>=2 (from requests>=2.31.0->o11y==0.1.0)\n",
      "  Using cached charset_normalizer-3.3.2-cp311-cp311-manylinux_2_17_x86_64.manylinux2014_x86_64.whl.metadata (33 kB)\n",
      "Collecting idna<4,>=2.5 (from requests>=2.31.0->o11y==0.1.0)\n",
      "  Using cached idna-3.7-py3-none-any.whl.metadata (9.9 kB)\n",
      "Collecting urllib3<3,>=1.21.1 (from requests>=2.31.0->o11y==0.1.0)\n",
      "  Using cached urllib3-2.2.1-py3-none-any.whl.metadata (6.4 kB)\n",
      "Collecting certifi>=2017.4.17 (from requests>=2.31.0->o11y==0.1.0)\n",
      "  Using cached certifi-2024.2.2-py3-none-any.whl.metadata (2.2 kB)\n",
      "Using cached python_logging_loki-0.3.1-py3-none-any.whl (7.0 kB)\n",
      "Using cached requests-2.31.0-py3-none-any.whl (62 kB)\n",
      "Using cached certifi-2024.2.2-py3-none-any.whl (163 kB)\n",
      "Using cached charset_normalizer-3.3.2-cp311-cp311-manylinux_2_17_x86_64.manylinux2014_x86_64.whl (140 kB)\n",
      "Using cached idna-3.7-py3-none-any.whl (66 kB)\n",
      "Using cached rfc3339-6.2-py3-none-any.whl (5.5 kB)\n",
      "Using cached urllib3-2.2.1-py3-none-any.whl (121 kB)\n",
      "Installing collected packages: rfc3339, urllib3, idna, charset-normalizer, certifi, requests, python-logging-loki, o11y\n",
      "  Attempting uninstall: urllib3\n",
      "    Found existing installation: urllib3 2.2.1\n",
      "    Uninstalling urllib3-2.2.1:\n",
      "      Successfully uninstalled urllib3-2.2.1\n",
      "  Attempting uninstall: idna\n",
      "    Found existing installation: idna 3.7\n",
      "    Uninstalling idna-3.7:\n",
      "      Successfully uninstalled idna-3.7\n",
      "  Attempting uninstall: charset-normalizer\n",
      "    Found existing installation: charset-normalizer 3.3.2\n",
      "    Uninstalling charset-normalizer-3.3.2:\n",
      "      Successfully uninstalled charset-normalizer-3.3.2\n",
      "  Attempting uninstall: certifi\n",
      "    Found existing installation: certifi 2024.2.2\n",
      "    Uninstalling certifi-2024.2.2:\n",
      "      Successfully uninstalled certifi-2024.2.2\n",
      "  Attempting uninstall: requests\n",
      "    Found existing installation: requests 2.31.0\n",
      "    Uninstalling requests-2.31.0:\n",
      "      Successfully uninstalled requests-2.31.0\n",
      "Successfully installed certifi-2024.2.2 charset-normalizer-3.3.2 idna-3.7 o11y-0.1.0 python-logging-loki-0.3.1 requests-2.31.0 rfc3339-6.2 urllib3-2.2.1\n"
     ]
    }
   ],
   "source": [
    "# Editable install for development\n",
    "# In real use this should be \"pip install o11y\"\n",
    "!pip install ./dist/*.whl --force-reinstall"
   ]
  },
  {
   "cell_type": "code",
   "execution_count": 2,
   "id": "b3a03c39-891a-4524-a258-36f1a7104dcf",
   "metadata": {},
   "outputs": [],
   "source": [
    "import o11y"
   ]
  },
  {
   "cell_type": "code",
   "execution_count": 3,
   "id": "fc49064e-9974-4d7f-9ef1-c08d9fb06087",
   "metadata": {},
   "outputs": [
    {
     "name": "stdout",
     "output_type": "stream",
     "text": [
      "83bcaff6228b39bbe431af5e19fb4368e2a03dd3@localhost:8000\n"
     ]
    }
   ],
   "source": [
    "import os\n",
    "# Verify we have credentials set in environment\n",
    "# In principle it should be possible to do \"o11y login\" to set this from the command line\n",
    "print(os.environ['GF_AI_TRAINING_CREDS'])"
   ]
  },
  {
   "cell_type": "code",
   "execution_count": 10,
   "id": "e6a85341-29d2-4e19-b7e9-429c5c7f6d95",
   "metadata": {},
   "outputs": [
    {
     "name": "stderr",
     "output_type": "stream",
     "text": [
      "--- Logging error ---\n",
      "Traceback (most recent call last):\n",
      "  File \"/opt/conda/lib/python3.11/site-packages/logging_loki/handlers.py\", line 81, in emit\n",
      "    self.emitter(record, self.format(record))\n",
      "  File \"/opt/conda/lib/python3.11/site-packages/logging_loki/emitter.py\", line 57, in __call__\n",
      "    raise ValueError(\"Unexpected Loki API response status code: {0}\".format(resp.status_code))\n",
      "ValueError: Unexpected Loki API response status code: 200\n",
      "Call stack:\n",
      "  File \"<frozen runpy>\", line 198, in _run_module_as_main\n",
      "  File \"<frozen runpy>\", line 88, in _run_code\n",
      "  File \"/opt/conda/lib/python3.11/site-packages/ipykernel_launcher.py\", line 18, in <module>\n",
      "    app.launch_new_instance()\n",
      "  File \"/opt/conda/lib/python3.11/site-packages/traitlets/config/application.py\", line 1075, in launch_instance\n",
      "    app.start()\n",
      "  File \"/opt/conda/lib/python3.11/site-packages/ipykernel/kernelapp.py\", line 739, in start\n",
      "    self.io_loop.start()\n",
      "  File \"/opt/conda/lib/python3.11/site-packages/tornado/platform/asyncio.py\", line 205, in start\n",
      "    self.asyncio_loop.run_forever()\n",
      "  File \"/opt/conda/lib/python3.11/asyncio/base_events.py\", line 608, in run_forever\n",
      "    self._run_once()\n",
      "  File \"/opt/conda/lib/python3.11/asyncio/base_events.py\", line 1936, in _run_once\n",
      "    handle._run()\n",
      "  File \"/opt/conda/lib/python3.11/asyncio/events.py\", line 84, in _run\n",
      "    self._context.run(self._callback, *self._args)\n",
      "  File \"/opt/conda/lib/python3.11/site-packages/ipykernel/kernelbase.py\", line 545, in dispatch_queue\n",
      "    await self.process_one()\n",
      "  File \"/opt/conda/lib/python3.11/site-packages/ipykernel/kernelbase.py\", line 534, in process_one\n",
      "    await dispatch(*args)\n",
      "  File \"/opt/conda/lib/python3.11/site-packages/ipykernel/kernelbase.py\", line 437, in dispatch_shell\n",
      "    await result\n",
      "  File \"/opt/conda/lib/python3.11/site-packages/ipykernel/ipkernel.py\", line 359, in execute_request\n",
      "    await super().execute_request(stream, ident, parent)\n",
      "  File \"/opt/conda/lib/python3.11/site-packages/ipykernel/kernelbase.py\", line 778, in execute_request\n",
      "    reply_content = await reply_content\n",
      "  File \"/opt/conda/lib/python3.11/site-packages/ipykernel/ipkernel.py\", line 446, in do_execute\n",
      "    res = shell.run_cell(\n",
      "  File \"/opt/conda/lib/python3.11/site-packages/ipykernel/zmqshell.py\", line 549, in run_cell\n",
      "    return super().run_cell(*args, **kwargs)\n",
      "  File \"/opt/conda/lib/python3.11/site-packages/IPython/core/interactiveshell.py\", line 3075, in run_cell\n",
      "    result = self._run_cell(\n",
      "  File \"/opt/conda/lib/python3.11/site-packages/IPython/core/interactiveshell.py\", line 3130, in _run_cell\n",
      "    result = runner(coro)\n",
      "  File \"/opt/conda/lib/python3.11/site-packages/IPython/core/async_helpers.py\", line 129, in _pseudo_sync_runner\n",
      "    coro.send(None)\n",
      "  File \"/opt/conda/lib/python3.11/site-packages/IPython/core/interactiveshell.py\", line 3334, in run_cell_async\n",
      "    has_raised = await self.run_ast_nodes(code_ast.body, cell_name,\n",
      "  File \"/opt/conda/lib/python3.11/site-packages/IPython/core/interactiveshell.py\", line 3517, in run_ast_nodes\n",
      "    if await self.run_code(code, result, async_=asy):\n",
      "  File \"/opt/conda/lib/python3.11/site-packages/IPython/core/interactiveshell.py\", line 3577, in run_code\n",
      "    exec(code_obj, self.user_global_ns, self.user_ns)\n",
      "  File \"/tmp/ipykernel_94/1744943448.py\", line 31, in <module>\n",
      "    o11y.log({\"accuracy\": acc, \"loss\": loss})\n",
      "  File \"/opt/conda/lib/python3.11/site-packages/o11y/exported/log.py\", line 10, in log\n",
      "    client.send_log(log)\n",
      "  File \"/opt/conda/lib/python3.11/site-packages/o11y/_internal/client.py\", line 139, in send_log\n",
      "    self.custom_logger.log(logging.INFO, log)\n",
      "  File \"/opt/conda/lib/python3.11/logging/__init__.py\", line 1559, in log\n",
      "    self._log(level, msg, args, **kwargs)\n",
      "  File \"/opt/conda/lib/python3.11/logging/__init__.py\", line 1634, in _log\n",
      "    self.handle(record)\n",
      "  File \"/opt/conda/lib/python3.11/logging/__init__.py\", line 1644, in handle\n",
      "    self.callHandlers(record)\n",
      "  File \"/opt/conda/lib/python3.11/logging/__init__.py\", line 1706, in callHandlers\n",
      "    hdlr.handle(record)\n",
      "  File \"/opt/conda/lib/python3.11/logging/__init__.py\", line 978, in handle\n",
      "    self.emit(record)\n",
      "  File \"/opt/conda/lib/python3.11/site-packages/logging_loki/handlers.py\", line 83, in emit\n",
      "    self.handleError(record)\n",
      "Message: {'accuracy': 0.48037282168706974, 'loss': 0.4611996132758005}\n",
      "Arguments: ()\n",
      "2024-05-03 23:12:56,633 - o11y._internal.client-ai-training-o11y-client - INFO - {'accuracy': 0.48037282168706974, 'loss': 0.4611996132758005}\n",
      "--- Logging error ---\n",
      "Traceback (most recent call last):\n",
      "  File \"/opt/conda/lib/python3.11/site-packages/logging_loki/handlers.py\", line 81, in emit\n",
      "    self.emitter(record, self.format(record))\n",
      "  File \"/opt/conda/lib/python3.11/site-packages/logging_loki/emitter.py\", line 57, in __call__\n",
      "    raise ValueError(\"Unexpected Loki API response status code: {0}\".format(resp.status_code))\n",
      "ValueError: Unexpected Loki API response status code: 200\n",
      "Call stack:\n",
      "  File \"<frozen runpy>\", line 198, in _run_module_as_main\n",
      "  File \"<frozen runpy>\", line 88, in _run_code\n",
      "  File \"/opt/conda/lib/python3.11/site-packages/ipykernel_launcher.py\", line 18, in <module>\n",
      "    app.launch_new_instance()\n",
      "  File \"/opt/conda/lib/python3.11/site-packages/traitlets/config/application.py\", line 1075, in launch_instance\n",
      "    app.start()\n",
      "  File \"/opt/conda/lib/python3.11/site-packages/ipykernel/kernelapp.py\", line 739, in start\n",
      "    self.io_loop.start()\n",
      "  File \"/opt/conda/lib/python3.11/site-packages/tornado/platform/asyncio.py\", line 205, in start\n",
      "    self.asyncio_loop.run_forever()\n",
      "  File \"/opt/conda/lib/python3.11/asyncio/base_events.py\", line 608, in run_forever\n",
      "    self._run_once()\n",
      "  File \"/opt/conda/lib/python3.11/asyncio/base_events.py\", line 1936, in _run_once\n",
      "    handle._run()\n",
      "  File \"/opt/conda/lib/python3.11/asyncio/events.py\", line 84, in _run\n",
      "    self._context.run(self._callback, *self._args)\n",
      "  File \"/opt/conda/lib/python3.11/site-packages/ipykernel/kernelbase.py\", line 545, in dispatch_queue\n",
      "    await self.process_one()\n",
      "  File \"/opt/conda/lib/python3.11/site-packages/ipykernel/kernelbase.py\", line 534, in process_one\n",
      "    await dispatch(*args)\n",
      "  File \"/opt/conda/lib/python3.11/site-packages/ipykernel/kernelbase.py\", line 437, in dispatch_shell\n",
      "    await result\n",
      "  File \"/opt/conda/lib/python3.11/site-packages/ipykernel/ipkernel.py\", line 359, in execute_request\n",
      "    await super().execute_request(stream, ident, parent)\n",
      "  File \"/opt/conda/lib/python3.11/site-packages/ipykernel/kernelbase.py\", line 778, in execute_request\n",
      "    reply_content = await reply_content\n",
      "  File \"/opt/conda/lib/python3.11/site-packages/ipykernel/ipkernel.py\", line 446, in do_execute\n",
      "    res = shell.run_cell(\n",
      "  File \"/opt/conda/lib/python3.11/site-packages/ipykernel/zmqshell.py\", line 549, in run_cell\n",
      "    return super().run_cell(*args, **kwargs)\n",
      "  File \"/opt/conda/lib/python3.11/site-packages/IPython/core/interactiveshell.py\", line 3075, in run_cell\n",
      "    result = self._run_cell(\n",
      "  File \"/opt/conda/lib/python3.11/site-packages/IPython/core/interactiveshell.py\", line 3130, in _run_cell\n",
      "    result = runner(coro)\n",
      "  File \"/opt/conda/lib/python3.11/site-packages/IPython/core/async_helpers.py\", line 129, in _pseudo_sync_runner\n",
      "    coro.send(None)\n",
      "  File \"/opt/conda/lib/python3.11/site-packages/IPython/core/interactiveshell.py\", line 3334, in run_cell_async\n",
      "    has_raised = await self.run_ast_nodes(code_ast.body, cell_name,\n",
      "  File \"/opt/conda/lib/python3.11/site-packages/IPython/core/interactiveshell.py\", line 3517, in run_ast_nodes\n",
      "    if await self.run_code(code, result, async_=asy):\n",
      "  File \"/opt/conda/lib/python3.11/site-packages/IPython/core/interactiveshell.py\", line 3577, in run_code\n",
      "    exec(code_obj, self.user_global_ns, self.user_ns)\n",
      "  File \"/tmp/ipykernel_94/1744943448.py\", line 31, in <module>\n",
      "    o11y.log({\"accuracy\": acc, \"loss\": loss})\n",
      "  File \"/opt/conda/lib/python3.11/site-packages/o11y/exported/log.py\", line 10, in log\n",
      "    client.send_log(log)\n",
      "  File \"/opt/conda/lib/python3.11/site-packages/o11y/_internal/client.py\", line 139, in send_log\n",
      "    self.custom_logger.log(logging.INFO, log)\n",
      "  File \"/opt/conda/lib/python3.11/logging/__init__.py\", line 1559, in log\n",
      "    self._log(level, msg, args, **kwargs)\n",
      "  File \"/opt/conda/lib/python3.11/logging/__init__.py\", line 1634, in _log\n",
      "    self.handle(record)\n",
      "  File \"/opt/conda/lib/python3.11/logging/__init__.py\", line 1644, in handle\n",
      "    self.callHandlers(record)\n",
      "  File \"/opt/conda/lib/python3.11/logging/__init__.py\", line 1706, in callHandlers\n",
      "    hdlr.handle(record)\n",
      "  File \"/opt/conda/lib/python3.11/logging/__init__.py\", line 978, in handle\n",
      "    self.emit(record)\n",
      "  File \"/opt/conda/lib/python3.11/site-packages/logging_loki/handlers.py\", line 83, in emit\n",
      "    self.handleError(record)\n",
      "Message: {'accuracy': 0.8327567010711399, 'loss': 0.37886422727708424}\n",
      "Arguments: ()\n",
      "2024-05-03 23:12:56,638 - o11y._internal.client-ai-training-o11y-client - INFO - {'accuracy': 0.8327567010711399, 'loss': 0.37886422727708424}\n",
      "--- Logging error ---\n",
      "Traceback (most recent call last):\n",
      "  File \"/opt/conda/lib/python3.11/site-packages/logging_loki/handlers.py\", line 81, in emit\n",
      "    self.emitter(record, self.format(record))\n",
      "  File \"/opt/conda/lib/python3.11/site-packages/logging_loki/emitter.py\", line 57, in __call__\n",
      "    raise ValueError(\"Unexpected Loki API response status code: {0}\".format(resp.status_code))\n",
      "ValueError: Unexpected Loki API response status code: 200\n",
      "Call stack:\n",
      "  File \"<frozen runpy>\", line 198, in _run_module_as_main\n",
      "  File \"<frozen runpy>\", line 88, in _run_code\n",
      "  File \"/opt/conda/lib/python3.11/site-packages/ipykernel_launcher.py\", line 18, in <module>\n",
      "    app.launch_new_instance()\n",
      "  File \"/opt/conda/lib/python3.11/site-packages/traitlets/config/application.py\", line 1075, in launch_instance\n",
      "    app.start()\n",
      "  File \"/opt/conda/lib/python3.11/site-packages/ipykernel/kernelapp.py\", line 739, in start\n",
      "    self.io_loop.start()\n",
      "  File \"/opt/conda/lib/python3.11/site-packages/tornado/platform/asyncio.py\", line 205, in start\n",
      "    self.asyncio_loop.run_forever()\n",
      "  File \"/opt/conda/lib/python3.11/asyncio/base_events.py\", line 608, in run_forever\n",
      "    self._run_once()\n",
      "  File \"/opt/conda/lib/python3.11/asyncio/base_events.py\", line 1936, in _run_once\n",
      "    handle._run()\n",
      "  File \"/opt/conda/lib/python3.11/asyncio/events.py\", line 84, in _run\n",
      "    self._context.run(self._callback, *self._args)\n",
      "  File \"/opt/conda/lib/python3.11/site-packages/ipykernel/kernelbase.py\", line 545, in dispatch_queue\n",
      "    await self.process_one()\n",
      "  File \"/opt/conda/lib/python3.11/site-packages/ipykernel/kernelbase.py\", line 534, in process_one\n",
      "    await dispatch(*args)\n",
      "  File \"/opt/conda/lib/python3.11/site-packages/ipykernel/kernelbase.py\", line 437, in dispatch_shell\n",
      "    await result\n",
      "  File \"/opt/conda/lib/python3.11/site-packages/ipykernel/ipkernel.py\", line 359, in execute_request\n",
      "    await super().execute_request(stream, ident, parent)\n",
      "  File \"/opt/conda/lib/python3.11/site-packages/ipykernel/kernelbase.py\", line 778, in execute_request\n",
      "    reply_content = await reply_content\n",
      "  File \"/opt/conda/lib/python3.11/site-packages/ipykernel/ipkernel.py\", line 446, in do_execute\n",
      "    res = shell.run_cell(\n",
      "  File \"/opt/conda/lib/python3.11/site-packages/ipykernel/zmqshell.py\", line 549, in run_cell\n",
      "    return super().run_cell(*args, **kwargs)\n",
      "  File \"/opt/conda/lib/python3.11/site-packages/IPython/core/interactiveshell.py\", line 3075, in run_cell\n",
      "    result = self._run_cell(\n",
      "  File \"/opt/conda/lib/python3.11/site-packages/IPython/core/interactiveshell.py\", line 3130, in _run_cell\n",
      "    result = runner(coro)\n",
      "  File \"/opt/conda/lib/python3.11/site-packages/IPython/core/async_helpers.py\", line 129, in _pseudo_sync_runner\n",
      "    coro.send(None)\n",
      "  File \"/opt/conda/lib/python3.11/site-packages/IPython/core/interactiveshell.py\", line 3334, in run_cell_async\n",
      "    has_raised = await self.run_ast_nodes(code_ast.body, cell_name,\n",
      "  File \"/opt/conda/lib/python3.11/site-packages/IPython/core/interactiveshell.py\", line 3517, in run_ast_nodes\n",
      "    if await self.run_code(code, result, async_=asy):\n",
      "  File \"/opt/conda/lib/python3.11/site-packages/IPython/core/interactiveshell.py\", line 3577, in run_code\n",
      "    exec(code_obj, self.user_global_ns, self.user_ns)\n",
      "  File \"/tmp/ipykernel_94/1744943448.py\", line 31, in <module>\n",
      "    o11y.log({\"accuracy\": acc, \"loss\": loss})\n",
      "  File \"/opt/conda/lib/python3.11/site-packages/o11y/exported/log.py\", line 10, in log\n",
      "    client.send_log(log)\n",
      "  File \"/opt/conda/lib/python3.11/site-packages/o11y/_internal/client.py\", line 139, in send_log\n",
      "    self.custom_logger.log(logging.INFO, log)\n",
      "  File \"/opt/conda/lib/python3.11/logging/__init__.py\", line 1559, in log\n",
      "    self._log(level, msg, args, **kwargs)\n",
      "  File \"/opt/conda/lib/python3.11/logging/__init__.py\", line 1634, in _log\n",
      "    self.handle(record)\n",
      "  File \"/opt/conda/lib/python3.11/logging/__init__.py\", line 1644, in handle\n",
      "    self.callHandlers(record)\n",
      "  File \"/opt/conda/lib/python3.11/logging/__init__.py\", line 1706, in callHandlers\n",
      "    hdlr.handle(record)\n",
      "  File \"/opt/conda/lib/python3.11/logging/__init__.py\", line 978, in handle\n",
      "    self.emit(record)\n",
      "  File \"/opt/conda/lib/python3.11/site-packages/logging_loki/handlers.py\", line 83, in emit\n",
      "    self.handleError(record)\n",
      "Message: {'accuracy': 0.8378506809335033, 'loss': 0.2747658631788615}\n",
      "Arguments: ()\n",
      "2024-05-03 23:12:56,642 - o11y._internal.client-ai-training-o11y-client - INFO - {'accuracy': 0.8378506809335033, 'loss': 0.2747658631788615}\n",
      "--- Logging error ---\n",
      "Traceback (most recent call last):\n",
      "  File \"/opt/conda/lib/python3.11/site-packages/logging_loki/handlers.py\", line 81, in emit\n",
      "    self.emitter(record, self.format(record))\n",
      "  File \"/opt/conda/lib/python3.11/site-packages/logging_loki/emitter.py\", line 57, in __call__\n",
      "    raise ValueError(\"Unexpected Loki API response status code: {0}\".format(resp.status_code))\n",
      "ValueError: Unexpected Loki API response status code: 200\n",
      "Call stack:\n",
      "  File \"<frozen runpy>\", line 198, in _run_module_as_main\n",
      "  File \"<frozen runpy>\", line 88, in _run_code\n",
      "  File \"/opt/conda/lib/python3.11/site-packages/ipykernel_launcher.py\", line 18, in <module>\n",
      "    app.launch_new_instance()\n",
      "  File \"/opt/conda/lib/python3.11/site-packages/traitlets/config/application.py\", line 1075, in launch_instance\n",
      "    app.start()\n",
      "  File \"/opt/conda/lib/python3.11/site-packages/ipykernel/kernelapp.py\", line 739, in start\n",
      "    self.io_loop.start()\n",
      "  File \"/opt/conda/lib/python3.11/site-packages/tornado/platform/asyncio.py\", line 205, in start\n",
      "    self.asyncio_loop.run_forever()\n",
      "  File \"/opt/conda/lib/python3.11/asyncio/base_events.py\", line 608, in run_forever\n",
      "    self._run_once()\n",
      "  File \"/opt/conda/lib/python3.11/asyncio/base_events.py\", line 1936, in _run_once\n",
      "    handle._run()\n",
      "  File \"/opt/conda/lib/python3.11/asyncio/events.py\", line 84, in _run\n",
      "    self._context.run(self._callback, *self._args)\n",
      "  File \"/opt/conda/lib/python3.11/site-packages/ipykernel/kernelbase.py\", line 545, in dispatch_queue\n",
      "    await self.process_one()\n",
      "  File \"/opt/conda/lib/python3.11/site-packages/ipykernel/kernelbase.py\", line 534, in process_one\n",
      "    await dispatch(*args)\n",
      "  File \"/opt/conda/lib/python3.11/site-packages/ipykernel/kernelbase.py\", line 437, in dispatch_shell\n",
      "    await result\n",
      "  File \"/opt/conda/lib/python3.11/site-packages/ipykernel/ipkernel.py\", line 359, in execute_request\n",
      "    await super().execute_request(stream, ident, parent)\n",
      "  File \"/opt/conda/lib/python3.11/site-packages/ipykernel/kernelbase.py\", line 778, in execute_request\n",
      "    reply_content = await reply_content\n",
      "  File \"/opt/conda/lib/python3.11/site-packages/ipykernel/ipkernel.py\", line 446, in do_execute\n",
      "    res = shell.run_cell(\n",
      "  File \"/opt/conda/lib/python3.11/site-packages/ipykernel/zmqshell.py\", line 549, in run_cell\n",
      "    return super().run_cell(*args, **kwargs)\n",
      "  File \"/opt/conda/lib/python3.11/site-packages/IPython/core/interactiveshell.py\", line 3075, in run_cell\n",
      "    result = self._run_cell(\n",
      "  File \"/opt/conda/lib/python3.11/site-packages/IPython/core/interactiveshell.py\", line 3130, in _run_cell\n",
      "    result = runner(coro)\n",
      "  File \"/opt/conda/lib/python3.11/site-packages/IPython/core/async_helpers.py\", line 129, in _pseudo_sync_runner\n",
      "    coro.send(None)\n",
      "  File \"/opt/conda/lib/python3.11/site-packages/IPython/core/interactiveshell.py\", line 3334, in run_cell_async\n",
      "    has_raised = await self.run_ast_nodes(code_ast.body, cell_name,\n",
      "  File \"/opt/conda/lib/python3.11/site-packages/IPython/core/interactiveshell.py\", line 3517, in run_ast_nodes\n",
      "    if await self.run_code(code, result, async_=asy):\n",
      "  File \"/opt/conda/lib/python3.11/site-packages/IPython/core/interactiveshell.py\", line 3577, in run_code\n",
      "    exec(code_obj, self.user_global_ns, self.user_ns)\n",
      "  File \"/tmp/ipykernel_94/1744943448.py\", line 31, in <module>\n",
      "    o11y.log({\"accuracy\": acc, \"loss\": loss})\n",
      "  File \"/opt/conda/lib/python3.11/site-packages/o11y/exported/log.py\", line 10, in log\n",
      "    client.send_log(log)\n",
      "  File \"/opt/conda/lib/python3.11/site-packages/o11y/_internal/client.py\", line 139, in send_log\n",
      "    self.custom_logger.log(logging.INFO, log)\n",
      "  File \"/opt/conda/lib/python3.11/logging/__init__.py\", line 1559, in log\n",
      "    self._log(level, msg, args, **kwargs)\n",
      "  File \"/opt/conda/lib/python3.11/logging/__init__.py\", line 1634, in _log\n",
      "    self.handle(record)\n",
      "  File \"/opt/conda/lib/python3.11/logging/__init__.py\", line 1644, in handle\n",
      "    self.callHandlers(record)\n",
      "  File \"/opt/conda/lib/python3.11/logging/__init__.py\", line 1706, in callHandlers\n",
      "    hdlr.handle(record)\n",
      "  File \"/opt/conda/lib/python3.11/logging/__init__.py\", line 978, in handle\n",
      "    self.emit(record)\n",
      "  File \"/opt/conda/lib/python3.11/site-packages/logging_loki/handlers.py\", line 83, in emit\n",
      "    self.handleError(record)\n",
      "Message: {'accuracy': 0.9056050202833931, 'loss': 0.14527804194072716}\n",
      "Arguments: ()\n",
      "2024-05-03 23:12:56,646 - o11y._internal.client-ai-training-o11y-client - INFO - {'accuracy': 0.9056050202833931, 'loss': 0.14527804194072716}\n",
      "--- Logging error ---\n",
      "Traceback (most recent call last):\n",
      "  File \"/opt/conda/lib/python3.11/site-packages/logging_loki/handlers.py\", line 81, in emit\n",
      "    self.emitter(record, self.format(record))\n",
      "  File \"/opt/conda/lib/python3.11/site-packages/logging_loki/emitter.py\", line 57, in __call__\n",
      "    raise ValueError(\"Unexpected Loki API response status code: {0}\".format(resp.status_code))\n",
      "ValueError: Unexpected Loki API response status code: 200\n",
      "Call stack:\n",
      "  File \"<frozen runpy>\", line 198, in _run_module_as_main\n",
      "  File \"<frozen runpy>\", line 88, in _run_code\n",
      "  File \"/opt/conda/lib/python3.11/site-packages/ipykernel_launcher.py\", line 18, in <module>\n",
      "    app.launch_new_instance()\n",
      "  File \"/opt/conda/lib/python3.11/site-packages/traitlets/config/application.py\", line 1075, in launch_instance\n",
      "    app.start()\n",
      "  File \"/opt/conda/lib/python3.11/site-packages/ipykernel/kernelapp.py\", line 739, in start\n",
      "    self.io_loop.start()\n",
      "  File \"/opt/conda/lib/python3.11/site-packages/tornado/platform/asyncio.py\", line 205, in start\n",
      "    self.asyncio_loop.run_forever()\n",
      "  File \"/opt/conda/lib/python3.11/asyncio/base_events.py\", line 608, in run_forever\n",
      "    self._run_once()\n",
      "  File \"/opt/conda/lib/python3.11/asyncio/base_events.py\", line 1936, in _run_once\n",
      "    handle._run()\n",
      "  File \"/opt/conda/lib/python3.11/asyncio/events.py\", line 84, in _run\n",
      "    self._context.run(self._callback, *self._args)\n",
      "  File \"/opt/conda/lib/python3.11/site-packages/ipykernel/kernelbase.py\", line 545, in dispatch_queue\n",
      "    await self.process_one()\n",
      "  File \"/opt/conda/lib/python3.11/site-packages/ipykernel/kernelbase.py\", line 534, in process_one\n",
      "    await dispatch(*args)\n",
      "  File \"/opt/conda/lib/python3.11/site-packages/ipykernel/kernelbase.py\", line 437, in dispatch_shell\n",
      "    await result\n",
      "  File \"/opt/conda/lib/python3.11/site-packages/ipykernel/ipkernel.py\", line 359, in execute_request\n",
      "    await super().execute_request(stream, ident, parent)\n",
      "  File \"/opt/conda/lib/python3.11/site-packages/ipykernel/kernelbase.py\", line 778, in execute_request\n",
      "    reply_content = await reply_content\n",
      "  File \"/opt/conda/lib/python3.11/site-packages/ipykernel/ipkernel.py\", line 446, in do_execute\n",
      "    res = shell.run_cell(\n",
      "  File \"/opt/conda/lib/python3.11/site-packages/ipykernel/zmqshell.py\", line 549, in run_cell\n",
      "    return super().run_cell(*args, **kwargs)\n",
      "  File \"/opt/conda/lib/python3.11/site-packages/IPython/core/interactiveshell.py\", line 3075, in run_cell\n",
      "    result = self._run_cell(\n",
      "  File \"/opt/conda/lib/python3.11/site-packages/IPython/core/interactiveshell.py\", line 3130, in _run_cell\n",
      "    result = runner(coro)\n",
      "  File \"/opt/conda/lib/python3.11/site-packages/IPython/core/async_helpers.py\", line 129, in _pseudo_sync_runner\n",
      "    coro.send(None)\n",
      "  File \"/opt/conda/lib/python3.11/site-packages/IPython/core/interactiveshell.py\", line 3334, in run_cell_async\n",
      "    has_raised = await self.run_ast_nodes(code_ast.body, cell_name,\n",
      "  File \"/opt/conda/lib/python3.11/site-packages/IPython/core/interactiveshell.py\", line 3517, in run_ast_nodes\n",
      "    if await self.run_code(code, result, async_=asy):\n",
      "  File \"/opt/conda/lib/python3.11/site-packages/IPython/core/interactiveshell.py\", line 3577, in run_code\n",
      "    exec(code_obj, self.user_global_ns, self.user_ns)\n",
      "  File \"/tmp/ipykernel_94/1744943448.py\", line 31, in <module>\n",
      "    o11y.log({\"accuracy\": acc, \"loss\": loss})\n",
      "  File \"/opt/conda/lib/python3.11/site-packages/o11y/exported/log.py\", line 10, in log\n",
      "    client.send_log(log)\n",
      "  File \"/opt/conda/lib/python3.11/site-packages/o11y/_internal/client.py\", line 139, in send_log\n",
      "    self.custom_logger.log(logging.INFO, log)\n",
      "  File \"/opt/conda/lib/python3.11/logging/__init__.py\", line 1559, in log\n",
      "    self._log(level, msg, args, **kwargs)\n",
      "  File \"/opt/conda/lib/python3.11/logging/__init__.py\", line 1634, in _log\n",
      "    self.handle(record)\n",
      "  File \"/opt/conda/lib/python3.11/logging/__init__.py\", line 1644, in handle\n",
      "    self.callHandlers(record)\n",
      "  File \"/opt/conda/lib/python3.11/logging/__init__.py\", line 1706, in callHandlers\n",
      "    hdlr.handle(record)\n",
      "  File \"/opt/conda/lib/python3.11/logging/__init__.py\", line 978, in handle\n",
      "    self.emit(record)\n",
      "  File \"/opt/conda/lib/python3.11/site-packages/logging_loki/handlers.py\", line 83, in emit\n",
      "    self.handleError(record)\n",
      "Message: {'accuracy': 0.8774964140194966, 'loss': 0.1342930881779633}\n",
      "Arguments: ()\n",
      "2024-05-03 23:12:56,650 - o11y._internal.client-ai-training-o11y-client - INFO - {'accuracy': 0.8774964140194966, 'loss': 0.1342930881779633}\n",
      "--- Logging error ---\n",
      "Traceback (most recent call last):\n",
      "  File \"/opt/conda/lib/python3.11/site-packages/logging_loki/handlers.py\", line 81, in emit\n",
      "    self.emitter(record, self.format(record))\n",
      "  File \"/opt/conda/lib/python3.11/site-packages/logging_loki/emitter.py\", line 57, in __call__\n",
      "    raise ValueError(\"Unexpected Loki API response status code: {0}\".format(resp.status_code))\n",
      "ValueError: Unexpected Loki API response status code: 200\n",
      "Call stack:\n",
      "  File \"<frozen runpy>\", line 198, in _run_module_as_main\n",
      "  File \"<frozen runpy>\", line 88, in _run_code\n",
      "  File \"/opt/conda/lib/python3.11/site-packages/ipykernel_launcher.py\", line 18, in <module>\n",
      "    app.launch_new_instance()\n",
      "  File \"/opt/conda/lib/python3.11/site-packages/traitlets/config/application.py\", line 1075, in launch_instance\n",
      "    app.start()\n",
      "  File \"/opt/conda/lib/python3.11/site-packages/ipykernel/kernelapp.py\", line 739, in start\n",
      "    self.io_loop.start()\n",
      "  File \"/opt/conda/lib/python3.11/site-packages/tornado/platform/asyncio.py\", line 205, in start\n",
      "    self.asyncio_loop.run_forever()\n",
      "  File \"/opt/conda/lib/python3.11/asyncio/base_events.py\", line 608, in run_forever\n",
      "    self._run_once()\n",
      "  File \"/opt/conda/lib/python3.11/asyncio/base_events.py\", line 1936, in _run_once\n",
      "    handle._run()\n",
      "  File \"/opt/conda/lib/python3.11/asyncio/events.py\", line 84, in _run\n",
      "    self._context.run(self._callback, *self._args)\n",
      "  File \"/opt/conda/lib/python3.11/site-packages/ipykernel/kernelbase.py\", line 545, in dispatch_queue\n",
      "    await self.process_one()\n",
      "  File \"/opt/conda/lib/python3.11/site-packages/ipykernel/kernelbase.py\", line 534, in process_one\n",
      "    await dispatch(*args)\n",
      "  File \"/opt/conda/lib/python3.11/site-packages/ipykernel/kernelbase.py\", line 437, in dispatch_shell\n",
      "    await result\n",
      "  File \"/opt/conda/lib/python3.11/site-packages/ipykernel/ipkernel.py\", line 359, in execute_request\n",
      "    await super().execute_request(stream, ident, parent)\n",
      "  File \"/opt/conda/lib/python3.11/site-packages/ipykernel/kernelbase.py\", line 778, in execute_request\n",
      "    reply_content = await reply_content\n",
      "  File \"/opt/conda/lib/python3.11/site-packages/ipykernel/ipkernel.py\", line 446, in do_execute\n",
      "    res = shell.run_cell(\n",
      "  File \"/opt/conda/lib/python3.11/site-packages/ipykernel/zmqshell.py\", line 549, in run_cell\n",
      "    return super().run_cell(*args, **kwargs)\n",
      "  File \"/opt/conda/lib/python3.11/site-packages/IPython/core/interactiveshell.py\", line 3075, in run_cell\n",
      "    result = self._run_cell(\n",
      "  File \"/opt/conda/lib/python3.11/site-packages/IPython/core/interactiveshell.py\", line 3130, in _run_cell\n",
      "    result = runner(coro)\n",
      "  File \"/opt/conda/lib/python3.11/site-packages/IPython/core/async_helpers.py\", line 129, in _pseudo_sync_runner\n",
      "    coro.send(None)\n",
      "  File \"/opt/conda/lib/python3.11/site-packages/IPython/core/interactiveshell.py\", line 3334, in run_cell_async\n",
      "    has_raised = await self.run_ast_nodes(code_ast.body, cell_name,\n",
      "  File \"/opt/conda/lib/python3.11/site-packages/IPython/core/interactiveshell.py\", line 3517, in run_ast_nodes\n",
      "    if await self.run_code(code, result, async_=asy):\n",
      "  File \"/opt/conda/lib/python3.11/site-packages/IPython/core/interactiveshell.py\", line 3577, in run_code\n",
      "    exec(code_obj, self.user_global_ns, self.user_ns)\n",
      "  File \"/tmp/ipykernel_94/1744943448.py\", line 31, in <module>\n",
      "    o11y.log({\"accuracy\": acc, \"loss\": loss})\n",
      "  File \"/opt/conda/lib/python3.11/site-packages/o11y/exported/log.py\", line 10, in log\n",
      "    client.send_log(log)\n",
      "  File \"/opt/conda/lib/python3.11/site-packages/o11y/_internal/client.py\", line 139, in send_log\n",
      "    self.custom_logger.log(logging.INFO, log)\n",
      "  File \"/opt/conda/lib/python3.11/logging/__init__.py\", line 1559, in log\n",
      "    self._log(level, msg, args, **kwargs)\n",
      "  File \"/opt/conda/lib/python3.11/logging/__init__.py\", line 1634, in _log\n",
      "    self.handle(record)\n",
      "  File \"/opt/conda/lib/python3.11/logging/__init__.py\", line 1644, in handle\n",
      "    self.callHandlers(record)\n",
      "  File \"/opt/conda/lib/python3.11/logging/__init__.py\", line 1706, in callHandlers\n",
      "    hdlr.handle(record)\n",
      "  File \"/opt/conda/lib/python3.11/logging/__init__.py\", line 978, in handle\n",
      "    self.emit(record)\n",
      "  File \"/opt/conda/lib/python3.11/site-packages/logging_loki/handlers.py\", line 83, in emit\n",
      "    self.handleError(record)\n",
      "Message: {'accuracy': 0.9641874643956766, 'loss': 0.04483947011121521}\n",
      "Arguments: ()\n",
      "2024-05-03 23:12:56,653 - o11y._internal.client-ai-training-o11y-client - INFO - {'accuracy': 0.9641874643956766, 'loss': 0.04483947011121521}\n",
      "--- Logging error ---\n",
      "Traceback (most recent call last):\n",
      "  File \"/opt/conda/lib/python3.11/site-packages/logging_loki/handlers.py\", line 81, in emit\n",
      "    self.emitter(record, self.format(record))\n",
      "  File \"/opt/conda/lib/python3.11/site-packages/logging_loki/emitter.py\", line 57, in __call__\n",
      "    raise ValueError(\"Unexpected Loki API response status code: {0}\".format(resp.status_code))\n",
      "ValueError: Unexpected Loki API response status code: 200\n",
      "Call stack:\n",
      "  File \"<frozen runpy>\", line 198, in _run_module_as_main\n",
      "  File \"<frozen runpy>\", line 88, in _run_code\n",
      "  File \"/opt/conda/lib/python3.11/site-packages/ipykernel_launcher.py\", line 18, in <module>\n",
      "    app.launch_new_instance()\n",
      "  File \"/opt/conda/lib/python3.11/site-packages/traitlets/config/application.py\", line 1075, in launch_instance\n",
      "    app.start()\n",
      "  File \"/opt/conda/lib/python3.11/site-packages/ipykernel/kernelapp.py\", line 739, in start\n",
      "    self.io_loop.start()\n",
      "  File \"/opt/conda/lib/python3.11/site-packages/tornado/platform/asyncio.py\", line 205, in start\n",
      "    self.asyncio_loop.run_forever()\n",
      "  File \"/opt/conda/lib/python3.11/asyncio/base_events.py\", line 608, in run_forever\n",
      "    self._run_once()\n",
      "  File \"/opt/conda/lib/python3.11/asyncio/base_events.py\", line 1936, in _run_once\n",
      "    handle._run()\n",
      "  File \"/opt/conda/lib/python3.11/asyncio/events.py\", line 84, in _run\n",
      "    self._context.run(self._callback, *self._args)\n",
      "  File \"/opt/conda/lib/python3.11/site-packages/ipykernel/kernelbase.py\", line 545, in dispatch_queue\n",
      "    await self.process_one()\n",
      "  File \"/opt/conda/lib/python3.11/site-packages/ipykernel/kernelbase.py\", line 534, in process_one\n",
      "    await dispatch(*args)\n",
      "  File \"/opt/conda/lib/python3.11/site-packages/ipykernel/kernelbase.py\", line 437, in dispatch_shell\n",
      "    await result\n",
      "  File \"/opt/conda/lib/python3.11/site-packages/ipykernel/ipkernel.py\", line 359, in execute_request\n",
      "    await super().execute_request(stream, ident, parent)\n",
      "  File \"/opt/conda/lib/python3.11/site-packages/ipykernel/kernelbase.py\", line 778, in execute_request\n",
      "    reply_content = await reply_content\n",
      "  File \"/opt/conda/lib/python3.11/site-packages/ipykernel/ipkernel.py\", line 446, in do_execute\n",
      "    res = shell.run_cell(\n",
      "  File \"/opt/conda/lib/python3.11/site-packages/ipykernel/zmqshell.py\", line 549, in run_cell\n",
      "    return super().run_cell(*args, **kwargs)\n",
      "  File \"/opt/conda/lib/python3.11/site-packages/IPython/core/interactiveshell.py\", line 3075, in run_cell\n",
      "    result = self._run_cell(\n",
      "  File \"/opt/conda/lib/python3.11/site-packages/IPython/core/interactiveshell.py\", line 3130, in _run_cell\n",
      "    result = runner(coro)\n",
      "  File \"/opt/conda/lib/python3.11/site-packages/IPython/core/async_helpers.py\", line 129, in _pseudo_sync_runner\n",
      "    coro.send(None)\n",
      "  File \"/opt/conda/lib/python3.11/site-packages/IPython/core/interactiveshell.py\", line 3334, in run_cell_async\n",
      "    has_raised = await self.run_ast_nodes(code_ast.body, cell_name,\n",
      "  File \"/opt/conda/lib/python3.11/site-packages/IPython/core/interactiveshell.py\", line 3517, in run_ast_nodes\n",
      "    if await self.run_code(code, result, async_=asy):\n",
      "  File \"/opt/conda/lib/python3.11/site-packages/IPython/core/interactiveshell.py\", line 3577, in run_code\n",
      "    exec(code_obj, self.user_global_ns, self.user_ns)\n",
      "  File \"/tmp/ipykernel_94/1744943448.py\", line 31, in <module>\n",
      "    o11y.log({\"accuracy\": acc, \"loss\": loss})\n",
      "  File \"/opt/conda/lib/python3.11/site-packages/o11y/exported/log.py\", line 10, in log\n",
      "    client.send_log(log)\n",
      "  File \"/opt/conda/lib/python3.11/site-packages/o11y/_internal/client.py\", line 139, in send_log\n",
      "    self.custom_logger.log(logging.INFO, log)\n",
      "  File \"/opt/conda/lib/python3.11/logging/__init__.py\", line 1559, in log\n",
      "    self._log(level, msg, args, **kwargs)\n",
      "  File \"/opt/conda/lib/python3.11/logging/__init__.py\", line 1634, in _log\n",
      "    self.handle(record)\n",
      "  File \"/opt/conda/lib/python3.11/logging/__init__.py\", line 1644, in handle\n",
      "    self.callHandlers(record)\n",
      "  File \"/opt/conda/lib/python3.11/logging/__init__.py\", line 1706, in callHandlers\n",
      "    hdlr.handle(record)\n",
      "  File \"/opt/conda/lib/python3.11/logging/__init__.py\", line 978, in handle\n",
      "    self.emit(record)\n",
      "  File \"/opt/conda/lib/python3.11/site-packages/logging_loki/handlers.py\", line 83, in emit\n",
      "    self.handleError(record)\n",
      "Message: {'accuracy': 0.9021568545306147, 'loss': 0.14375248634661233}\n",
      "Arguments: ()\n",
      "2024-05-03 23:12:56,657 - o11y._internal.client-ai-training-o11y-client - INFO - {'accuracy': 0.9021568545306147, 'loss': 0.14375248634661233}\n",
      "--- Logging error ---\n",
      "Traceback (most recent call last):\n",
      "  File \"/opt/conda/lib/python3.11/site-packages/logging_loki/handlers.py\", line 81, in emit\n",
      "    self.emitter(record, self.format(record))\n",
      "  File \"/opt/conda/lib/python3.11/site-packages/logging_loki/emitter.py\", line 57, in __call__\n",
      "    raise ValueError(\"Unexpected Loki API response status code: {0}\".format(resp.status_code))\n",
      "ValueError: Unexpected Loki API response status code: 200\n",
      "Call stack:\n",
      "  File \"<frozen runpy>\", line 198, in _run_module_as_main\n",
      "  File \"<frozen runpy>\", line 88, in _run_code\n",
      "  File \"/opt/conda/lib/python3.11/site-packages/ipykernel_launcher.py\", line 18, in <module>\n",
      "    app.launch_new_instance()\n",
      "  File \"/opt/conda/lib/python3.11/site-packages/traitlets/config/application.py\", line 1075, in launch_instance\n",
      "    app.start()\n",
      "  File \"/opt/conda/lib/python3.11/site-packages/ipykernel/kernelapp.py\", line 739, in start\n",
      "    self.io_loop.start()\n",
      "  File \"/opt/conda/lib/python3.11/site-packages/tornado/platform/asyncio.py\", line 205, in start\n",
      "    self.asyncio_loop.run_forever()\n",
      "  File \"/opt/conda/lib/python3.11/asyncio/base_events.py\", line 608, in run_forever\n",
      "    self._run_once()\n",
      "  File \"/opt/conda/lib/python3.11/asyncio/base_events.py\", line 1936, in _run_once\n",
      "    handle._run()\n",
      "  File \"/opt/conda/lib/python3.11/asyncio/events.py\", line 84, in _run\n",
      "    self._context.run(self._callback, *self._args)\n",
      "  File \"/opt/conda/lib/python3.11/site-packages/ipykernel/kernelbase.py\", line 545, in dispatch_queue\n",
      "    await self.process_one()\n",
      "  File \"/opt/conda/lib/python3.11/site-packages/ipykernel/kernelbase.py\", line 534, in process_one\n",
      "    await dispatch(*args)\n",
      "  File \"/opt/conda/lib/python3.11/site-packages/ipykernel/kernelbase.py\", line 437, in dispatch_shell\n",
      "    await result\n",
      "  File \"/opt/conda/lib/python3.11/site-packages/ipykernel/ipkernel.py\", line 359, in execute_request\n",
      "    await super().execute_request(stream, ident, parent)\n",
      "  File \"/opt/conda/lib/python3.11/site-packages/ipykernel/kernelbase.py\", line 778, in execute_request\n",
      "    reply_content = await reply_content\n",
      "  File \"/opt/conda/lib/python3.11/site-packages/ipykernel/ipkernel.py\", line 446, in do_execute\n",
      "    res = shell.run_cell(\n",
      "  File \"/opt/conda/lib/python3.11/site-packages/ipykernel/zmqshell.py\", line 549, in run_cell\n",
      "    return super().run_cell(*args, **kwargs)\n",
      "  File \"/opt/conda/lib/python3.11/site-packages/IPython/core/interactiveshell.py\", line 3075, in run_cell\n",
      "    result = self._run_cell(\n",
      "  File \"/opt/conda/lib/python3.11/site-packages/IPython/core/interactiveshell.py\", line 3130, in _run_cell\n",
      "    result = runner(coro)\n",
      "  File \"/opt/conda/lib/python3.11/site-packages/IPython/core/async_helpers.py\", line 129, in _pseudo_sync_runner\n",
      "    coro.send(None)\n",
      "  File \"/opt/conda/lib/python3.11/site-packages/IPython/core/interactiveshell.py\", line 3334, in run_cell_async\n",
      "    has_raised = await self.run_ast_nodes(code_ast.body, cell_name,\n",
      "  File \"/opt/conda/lib/python3.11/site-packages/IPython/core/interactiveshell.py\", line 3517, in run_ast_nodes\n",
      "    if await self.run_code(code, result, async_=asy):\n",
      "  File \"/opt/conda/lib/python3.11/site-packages/IPython/core/interactiveshell.py\", line 3577, in run_code\n",
      "    exec(code_obj, self.user_global_ns, self.user_ns)\n",
      "  File \"/tmp/ipykernel_94/1744943448.py\", line 31, in <module>\n",
      "    o11y.log({\"accuracy\": acc, \"loss\": loss})\n",
      "  File \"/opt/conda/lib/python3.11/site-packages/o11y/exported/log.py\", line 10, in log\n",
      "    client.send_log(log)\n",
      "  File \"/opt/conda/lib/python3.11/site-packages/o11y/_internal/client.py\", line 139, in send_log\n",
      "    self.custom_logger.log(logging.INFO, log)\n",
      "  File \"/opt/conda/lib/python3.11/logging/__init__.py\", line 1559, in log\n",
      "    self._log(level, msg, args, **kwargs)\n",
      "  File \"/opt/conda/lib/python3.11/logging/__init__.py\", line 1634, in _log\n",
      "    self.handle(record)\n",
      "  File \"/opt/conda/lib/python3.11/logging/__init__.py\", line 1644, in handle\n",
      "    self.callHandlers(record)\n",
      "  File \"/opt/conda/lib/python3.11/logging/__init__.py\", line 1706, in callHandlers\n",
      "    hdlr.handle(record)\n",
      "  File \"/opt/conda/lib/python3.11/logging/__init__.py\", line 978, in handle\n",
      "    self.emit(record)\n",
      "  File \"/opt/conda/lib/python3.11/site-packages/logging_loki/handlers.py\", line 83, in emit\n",
      "    self.handleError(record)\n",
      "Message: {'accuracy': 0.9267603225036217, 'loss': 0.1285421792189219}\n",
      "Arguments: ()\n",
      "2024-05-03 23:12:56,661 - o11y._internal.client-ai-training-o11y-client - INFO - {'accuracy': 0.9267603225036217, 'loss': 0.1285421792189219}\n"
     ]
    },
    {
     "name": "stdout",
     "output_type": "stream",
     "text": [
      "lr: 0.01\n",
      "epoch=2, accuracy=0.48037282168706974, loss=0.4611996132758005\n",
      "epoch=3, accuracy=0.8327567010711399, loss=0.37886422727708424\n",
      "epoch=4, accuracy=0.8378506809335033, loss=0.2747658631788615\n",
      "epoch=5, accuracy=0.9056050202833931, loss=0.14527804194072716\n",
      "epoch=6, accuracy=0.8774964140194966, loss=0.1342930881779633\n",
      "epoch=7, accuracy=0.9641874643956766, loss=0.04483947011121521\n",
      "epoch=8, accuracy=0.9021568545306147, loss=0.14375248634661233\n",
      "epoch=9, accuracy=0.9267603225036217, loss=0.1285421792189219\n"
     ]
    }
   ],
   "source": [
    "import random \n",
    "\n",
    "epochs = 10\n",
    "lr = 0.01\n",
    "\n",
    "run = o11y.init(\n",
    "    # Set the project where this run will be logged\n",
    "    project=\"my-awesome-project\",\n",
    "    # Track hyperparameters and run metadata\n",
    "    metadata={\n",
    "        \"config\": {\n",
    "            \"learning_rate\": lr,\n",
    "            \"epochs\": epochs,\n",
    "            \"feed_forward\": {\n",
    "                \"activation\": \"swiglu\",\n",
    "                \"d_model\": 1024,\n",
    "            }\n",
    "        },\n",
    "        \"git_commit\": \"some_hash_goes_here\",\n",
    "    },\n",
    ")\n",
    "\n",
    "offset = random.random() / 5\n",
    "print(f\"lr: {lr}\")\n",
    "\n",
    "# simulating a training run\n",
    "for epoch in range(2, epochs):\n",
    "    acc = 1 - 2**-epoch - random.random() / epoch - offset\n",
    "    loss = 2**-epoch + random.random() / epoch + offset\n",
    "    print(f\"epoch={epoch}, accuracy={acc}, loss={loss}\")\n",
    "    o11y.log({\"accuracy\": acc, \"loss\": loss})\n",
    "    if epoch == epochs:\n",
    "        o11y.update({\n",
    "            \"final_accuracy\": acc,\n",
    "            \"final_loss\": loss\n",
    "        })"
   ]
  }
 ],
 "metadata": {
  "kernelspec": {
   "display_name": "Python 3 (ipykernel)",
   "language": "python",
   "name": "python3"
  },
  "language_info": {
   "codemirror_mode": {
    "name": "ipython",
    "version": 3
   },
   "file_extension": ".py",
   "mimetype": "text/x-python",
   "name": "python",
   "nbconvert_exporter": "python",
   "pygments_lexer": "ipython3",
   "version": "3.11.9"
  }
 },
 "nbformat": 4,
 "nbformat_minor": 5
}
